Workbook

Sheet Instructions
A1: Security / Privacy NFR — Scoring Rubric & Instructions
A3: Purpose
A4: This workbook operationalizes the Security/Privacy non-functional requirement (Section 4.4 of the proposal). Each of four operating systems is scored on nine criteria at three time points (2015, 2020, 2025/26), producing a documented security-posture trend per platform.
A6: The 0–1–2 scale
A7: 0 = feature absent / undocumented. 1 = partial, optional, or limited. 2 = fully present, on by default, and documented.
A8: Each criterion's row gives the specific meaning of 0/1/2 for that criterion — use that wording, not a general impression.
A10: How to score (Scoring sheet)
A11: 1. Work one platform at a time, and within a platform one time point at a time (2015, then 2020, then 2025/26).
A12: 2. For each criterion, consult PUBLIC documentation only — official release notes, security/privacy whitepapers, developer documentation — for that platform at (approximately) that time point.
A13: 3. Enter 0, 1, or 2 in the score cell (dropdown provided). Enter the same four options' logic as the reliability study: if a platform did not exist at a time point (e.g., HarmonyOS in 2015, Fuchsia in 2015), enter “N/A” and note it.
A14: 4. In the matching Evidence column, paste the source (document title + URL + the date/version it refers to) that justifies the score. A score without a citable source is not usable in the paper.
A15: 5. Both co-authors should score independently where feasible, then reconcile — same two-rater discipline as the reliability study. IMPORTANT: keep each rater's independent scores in a separate copy BEFORE reconciling, so an inter-rater agreement figure can be reported.
... A21: The Trend sheet automatically computes each platform's total and average score per time point (excluding N/A), which becomes the security-posture-over-time chart in Section 5 of the paper.

Sheet Rubric
A1: ID | B1: Dimension | C1: Criterion | D1: Meaning of 0 / 1 / 2
A2: A1 | B2: Authentication | C2: Biometric authentication | D2: 0 = none; 1 = single modality (e.g., fingerprint only); 2 = multiple/advanced modalities (face + fingerprint, liveness detection)
A3: A2 | B3: Authentication | C3: Multi-factor / two-factor authentication | D3: 0 = not supported; 1 = optional/partial support; 2 = built-in and broadly supported across services
A4: A3 | B4: Authentication | C4: Secure boot / verified boot / hardware root of trust | D4: 0 = absent; 1 = partial or optional; 2 = enforced by default with hardware backing (TPM, Secure Enclave, etc.)
A5: D1 | B5: Data protection | C5: Encryption at rest (device/file-level) | D5: 0 = none; 1 = optional or partial; 2 = on by default, full-disk or file-based
A6: D2 | B6: Data protection | C6: Encryption in transit / secure networking defaults | D6: 0 = none; 1 = partial; 2 = enforced by default (TLS, encrypted sync, etc.)
A7: D3 | B7: Data protection | C7: On-device / private processing of sensitive data | D7: 0 = none, all cloud; 1 = some on-device processing; 2 = strong on-device / private-cloud guarantees documented
A8: T1 | B8: Transparency | C8: Transparency of AI / data handling (what leaves the device) | D8: 0 = undocumented; 1 = partially documented; 2 = clearly documented what is processed on-device vs. cloud
A9: T2 | B9: Transparency | C9: User-facing privacy controls / permission granularity | D9: 0 = coarse or none; 1 = moderate; 2 = fine-grained per-app/per-data permissions
A10: T3 | B10: Transparency | C10: Independent audit / compliance documentation | D10: 0 = none; 1 = some third-party or self-reported compliance; 2 = independent audit / formal certification documented

Sheet Scoring
A1: OS | B1: Time Point | C1: Crit ID | D1: Dimension | E1: Criterion | F1: Score (0/1/2/N/A) | G1: Evidence (source title + URL + date/version) | H1: Rater | I1: Rater 2 Score (Nijem) | J1: Rater 2 Evidence | K1: Final Score | L1: Reconciliation Notes
A2: Apple / iOS | B2: 2015 | C2: A1 | D2: Authentication | E2: Biometric authentication | F2: 1 | G2: iOS 9 (Sept 2015) supported Touch ID fingerprint authentication only — a single biometric modality (Face ID did not launch until iPhone X, 2017). Source: Apple, "iOS Security—White Paper," September 2015 (official primary source). | H2: M. Alhawarat | I2: 1 | J2: MacRumors, 'Touch ID' guide: Touch ID (fingerprint only) shipped on iPhone 5s (2013) through iPhone 6/6s-era devices; Face ID did not exist until 2017 -- https://www.macrumors.com/guide/touch-id/ (accessed 2026) | K2: 1 | L2: Agreed independently by both raters; no reconciliation needed.
A3: Apple / iOS | B3: 2015 | C3: A2 | D3: Authentication | E3: Multi-factor / two-factor authentication | F3: 2 | G3: Apple introduced mandatory two-factor authentication for Apple ID alongside iOS 9 / OS X El Capitan in September 2015 (building on two-step verification offered since 2013), combining password with a trusted-device code. Source: Apple iOS Security White Paper, September 2015; contemporaneous Apple ID 2FA rollout coverage. | H3: M. Alhawarat | I3: 1 | J3: KEPT AT 1 -- factual correction to co-author's source: 9to5Mac's contemporaneous Sept 2015 rollout post states 'all iCloud users CAN enable two-factor authentication today' (opt-in); mandatory *upgrading* from 2-step to 2FA did not begin until the iOS 11/macOS High Sierra betas in 2017 ('required to use some of the latest features') -- https://9to5mac.com/2015/07/08/apple-revamped-two-factor-login/ ; https://mobileidworld.com/2fa-security-new-ios-features-006156/ . Flagged for co-author: their 'mandatory in Sept 2015' claim appears to conflict with these contemporaneous sources. | K3: 1 | L3: RECONCILED (was 2/1): 9to5Mac's contemporaneous Sept 2015 source describes Apple ID 2FA as opt-in ('CAN enable'), not mandatory; mandatory upgrade prompts began only in 2017. Original 'mandatory' claim was a factual error, corrected via co-author's independent verification.
A4: Apple / iOS | B4: 2015 | C4: A3 | D4: Authentication | E4: Secure boot / verified boot / hardware root of trust | F4: 2 | G4: The Secure Enclave (present since the A7 chip, iPhone 5s) provided its own independent secure boot process and personalized software update path, separate from the application processor, maintaining Data Protection integrity even if the main kernel was compromised. Source: Apple iOS Security White Paper, September 2015 (official primary source, "Secure Enclave" section). | H4: M. Alhawarat | I4: 2 | J4: Apple, 'iOS Security' guide, iOS 8.3, April 2015 -- https://apple.com/vn/privacy/docs/iOS_Security_Guide.pdf -- documents secure boot chain enforced by default with hardware root of trust (Boot ROM) and Secure Enclave, already present at iOS 8.3. | K4: 2 | L4: Agreed independently by both raters; no reconciliation needed.
A5: Apple / iOS | B5: 2015 | C5: D1 | D5: Data protection | E5: Encryption at rest (device/file-level) | F5: 2 | G5: iOS Data Protection encrypted user data by default using class keys derived from the device UID and user passcode, entirely on-device, since iOS 8. Source: Apple iOS Security White Paper, September 2015. | H5: M. Alhawarat | I5: 2 | J5: Apple, 'iOS Security' guide, iOS 8.3, April 2015 -- https://apple.com/vn/privacy/docs/iOS_Security_Guide.pdf -- 'File Data Protection' section: on-by-default, file-based Data Protection encryption since iOS 8 (2014). | K5: 2 | L5: Agreed independently by both raters; no reconciliation needed.
A6: Apple / iOS | B6: 2015 | C6: D2 | D6: Data protection | E6: Encryption in transit / secure networking defaults | F6: 1 | G6: App Transport Security (ATS) was introduced with iOS 9 (Sept 2015), encouraging apps to use HTTPS, but enforcement for App Store submissions was not yet mandatory in 2015 (that deadline arrived in subsequent years) — assessed as partial/optional at this time point. | H6: M. Alhawarat | I6: 1 | J6: OWASP MASTG-KNOW-0071 / WWDC 2015 Session 706 notes: App Transport Security (ATS), introduced iOS 9 (Sept 2015), is on by default but developers could disable it via Info.plist with NO justification required until Jan 1, 2017 -- https://mas.owasp.org/MASTG/knowledge/ios/MASVS-NETWORK/MASTG-KNOW-0071/ ; https://mjtsai.com/blog/2015/07/17/ | K6: 1 | L6: Agreed independently by both raters; no reconciliation needed.
A7: Apple / iOS | B7: 2015 | C7: D3 | D7: Data protection | E7: On-device / private processing of sensitive data | F7: 1 | G7: On-device Data Protection kept user files encrypted locally by default, but Siri’s voice recognition and query processing in 2015 was substantially cloud-dependent (server-side processing), similar to contemporaneous voice assistants — a mixed picture rather than a comprehensive on-device guarantee. | H7: M. Alhawarat | I7: 1 | J7: Apple Support, 'About Touch ID advanced security technology': fingerprint matching performed entirely on-device in the Secure Enclave, never sent to Apple -- https://support.apple.com/en-us/105095 (general-purpose Siri/AI processing was cloud-based at this time; no comparable on-device AI documentation existed in 2015). | K7: 1 | L7: Agreed independently by both raters; no reconciliation needed.
A8: Apple / iOS | B8: 2015 | C8: T1 | D8: Transparency | E8: Transparency of AI / data handling (what leaves the device) | F8: 2 | G8: Apple publicly published a detailed, technical iOS Security White Paper (this Sept 2015 edition) describing cryptographic and data-handling mechanisms in depth — an unusually transparent practice for the OS industry at the time. Source: Apple iOS Security White Paper, September 2015. | H8: M. Alhawarat | I8: 1 | J8: Apple, 'iOS Security' guide, iOS 8.3, April 2015 -- https://apple.com/vn/privacy/docs/iOS_Security_Guide.pdf -- the April 2015 iOS Security Guide's table of contents has no dedicated section documenting what Siri/AI-type data is processed on-device vs. sent to Apple's servers, indicating limited documentation at this time point. (Kept at original independent assessment -- co-author reads the same White Paper as covering data-handling transparency more broadly; noted as an open disagreement rather than adopted.) | K8: 1 | L8: RECONCILED (was 2/1): The actual April 2015 iOS Security Guide (iOS 8.3) has no dedicated section on Siri/AI-type data handling specifically; general cryptographic documentation strength does not substitute for AI-data-handling-specific transparency, the literal criterion.
A9: Apple / iOS | B9: 2015 | C9: T2 | D9: Transparency | E9: User-facing privacy controls / permission granularity | F9: 2 | G9: iOS had an established, mature runtime permission model (location, contacts, photos, camera, microphone) with per-app user consent prompts since iOS 6 (2012), well ahead of most competitors by 2015. | H9: M. Alhawarat | I9: 2 | J9: Apple, 'iOS Security' guide, iOS 8.3, April 2015 -- https://apple.com/vn/privacy/docs/iOS_Security_Guide.pdf -- table of contents lists a dedicated 'Privacy controls' section covering per-app control of Location Services and other user data, already fine-grained by iOS 8.3 (April 2015). | K9: 2 | L9: Agreed independently by both raters; no reconciliation needed.
A10: Apple / iOS | B10: 2015 | C10: T3 | D10: Transparency | E10: Independent audit / compliance documentation | F10: 1 | G10: Apple’s security documentation in 2015 was self-published (the white paper itself); no evidence found of a formal, independent third-party audit or certification specific to iOS device security at this time, though Apple’s enterprise cloud services held some compliance certifications. | H10: M. Alhawarat | I10: 1 | J10: Apple, 'iOS Security' guide, iOS 8.3, April 2015 -- https://apple.com/vn/privacy/docs/iOS_Security_Guide.pdf -- table of contents lists a 'FIPS 140-2' section, i.e. formal cryptographic-module certification, but no independent audit of the OS/data-handling as a whole (self-reported/certification-program level). | K10: 1 | L10: Agreed independently by both raters; no reconciliation needed.
A11: Apple / iOS | B11: 2020 | C11: A1 | D11: Authentication | E11: Biometric authentication | F11: 2 | G11: By iOS 14 (2020), Face ID (introduced 2017) and Touch ID (retained on some models) together offered multiple biometric modalities with liveness/attention detection for Face ID. | H11: M. Alhawarat | I11: 2 | J11: Apple, 'Face ID Security' guide (Nov 2017, still current tech in 2020): Face ID uses TrueDepth camera with attention/liveness detection ('confirms attention by detecting the direction of your gaze... mitigate both digital and physical spoofing') -- https://www.apple.com/business-docs/FaceID_Security_Guide.pdf | K11: 2 | L11: Agreed independently by both raters; no reconciliation needed.
A12: Apple / iOS | B12: 2020 | C12: A2 | D12: Authentication | E12: Multi-factor / two-factor authentication | F12: 2 | G12: Two-factor authentication for Apple ID had become effectively mandatory for new accounts by this period and was broadly integrated across Apple services. | H12: M. Alhawarat | I12: 2 | J12: Apple Support, 'Two-factor authentication for Apple ID' (HT204915): 2FA required for all new Apple IDs and, once enabled on an existing ID, cannot be turned off -- built-in and broadly enforced across Apple ID/iCloud services by 2020 -- https://support.apple.com/en-us/HT204915 | K12: 2 | L12: Agreed independently by both raters; no reconciliation needed.
A13: Apple / iOS | B13: 2020 | C13: A3 | D13: Authentication | E13: Secure boot / verified boot / hardware root of trust | F13: 2 | G13: The Secure Enclave had matured further (e.g., A13-generation chips introducing formally verified cryptographic implementations), continuing independent secure boot and key management. | H13: M. Alhawarat | I13: 2 | J13: Apple, 'Apple Platform Security' guide (current) -- https://support.apple.com/en-bn/guide/security-pdf/secb3000f149/web -- secure boot chain / hardware root of trust unchanged in principle, now also extended to T2/Apple Silicon Secure Enclave on Mac. | K13: 2 | L13: Agreed independently by both raters; no reconciliation needed.
... A28: Apple / iOS | B28: 2025/26 | C28: T3 | D28: Transparency | E28: Independent audit / compliance documentation | F28: 2 | G28: Apple gave third-party auditors and independent security researchers early access to Private Cloud Compute’s Virtual Research Environment (VRE) before public launch, then published PCC source code (CloudAttestation, Thimble, splunkloggingd, srd_tools) and expanded its Apple Security Bounty program to cover PCC — a substantive, verifiable independent-audit mechanism, not merely a self-published claim. Source: 9to5Mac, "Apple shares Private Cloud Compute resources for researchers, expands Bug Bounty rewards" (Oct 2024); The Register (Oct 2024); The Hacker News (Oct 2024). | H28: M. Alhawarat | I28: 2 | J28: Apple Security Research, 'Security research on Private Cloud Compute' (24 Oct 2024): Apple released the PCC Security Guide, source code/binaries of key components, and a Virtual Research Environment so independent researchers can inspect and verify its privacy/security guarantees -- https://security.apple.com/blog/ (see 'Security research on Private Cloud Compute', 24 Oct 2024) | K28: 2 | L28: Agreed independently by both raters; no reconciliation needed.
A29: HarmonyOS | B29: 2015 | C29: A1 | D29: Authentication | E29: Biometric authentication | F29: N/A | G29: HarmonyOS did not exist in 2015 (Huawei announced/launched it in August 2019, initially for smart-screen/TV devices only). Scored N/A per protocol, not 0, since 0 would incorrectly imply the platform existed but lacked the feature. | H29: M. Alhawarat | I29: N/A | J29: HarmonyOS publicly launched Aug 2019 (Huawei Developer Conference); did not exist in 2015 -- https://en.wikipedia.org/wiki/HarmonyOS (per rubric Instructions sheet: N/A, not 0, for platforms that did not yet exist) | K29: N/A | L29: Agreed independently by both raters; no reconciliation needed.
A30: HarmonyOS | B30: 2015 | C30: A2 | D30: Authentication | E30: Multi-factor / two-factor authentication | F30: N/A | G30: HarmonyOS did not exist in 2015 (Huawei announced/launched it in August 2019, initially for smart-screen/TV devices only). Scored N/A per protocol, not 0, since 0 would incorrectly imply the platform existed but lacked the feature. | H30: M. Alhawarat | I30: N/A | J30: HarmonyOS publicly launched Aug 2019 (Huawei Developer Conference); did not exist in 2015 -- https://en.wikipedia.org/wiki/HarmonyOS (per rubric Instructions sheet: N/A, not 0, for platforms that did not yet exist) | K30: N/A | L30: Agreed independently by both raters; no reconciliation needed.
A31: HarmonyOS | B31: 2015 | C31: A3 | D31: Authentication | E31: Secure boot / verified boot / hardware root of trust | F31: N/A | G31: HarmonyOS did not exist in 2015 (Huawei announced/launched it in August 2019, initially for smart-screen/TV devices only). Scored N/A per protocol, not 0, since 0 would incorrectly imply the platform existed but lacked the feature. | H31: M. Alhawarat | I31: N/A | J31: HarmonyOS publicly launched Aug 2019 (Huawei Developer Conference); did not exist in 2015 -- https://en.wikipedia.org/wiki/HarmonyOS (per rubric Instructions sheet: N/A, not 0, for platforms that did not yet exist) | K31: N/A | L31: Agreed independently by both raters; no reconciliation needed.
A32: HarmonyOS | B32: 2015 | C32: D1 | D32: Data protection | E32: Encryption at rest (device/file-level) | F32: N/A | G32: HarmonyOS did not exist in 2015 (Huawei announced/launched it in August 2019, initially for smart-screen/TV devices only). Scored N/A per protocol, not 0, since 0 would incorrectly imply the platform existed but lacked the feature. | H32: M. Alhawarat | I32: N/A | J32: HarmonyOS publicly launched Aug 2019 (Huawei Developer Conference); did not exist in 2015 -- https://en.wikipedia.org/wiki/HarmonyOS (per rubric Instructions sheet: N/A, not 0, for platforms that did not yet exist) | K32: N/A | L32: Agreed independently by both raters; no reconciliation needed.
A33: HarmonyOS | B33: 2015 | C33: D2 | D33: Data protection | E33: Encryption in transit / secure networking defaults | F33: N/A | G33: HarmonyOS did not exist in 2015 (Huawei announced/launched it in August 2019, initially for smart-screen/TV devices only). Scored N/A per protocol, not 0, since 0 would incorrectly imply the platform existed but lacked the feature. | H33: M. Alhawarat | I33: N/A | J33: HarmonyOS publicly launched Aug 2019 (Huawei Developer Conference); did not exist in 2015 -- https://en.wikipedia.org/wiki/HarmonyOS (per rubric Instructions sheet: N/A, not 0, for platforms that did not yet exist) | K33: N/A | L33: Agreed independently by both raters; no reconciliation needed.
A34: HarmonyOS | B34: 2015 | C34: D3 | D34: Data protection | E34: On-device / private processing of sensitive data | F34: N/A | G34: HarmonyOS did not exist in 2015 (Huawei announced/launched it in August 2019, initially for smart-screen/TV devices only). Scored N/A per protocol, not 0, since 0 would incorrectly imply the platform existed but lacked the feature. | H34: M. Alhawarat | I34: N/A | J34: HarmonyOS publicly launched Aug 2019 (Huawei Developer Conference); did not exist in 2015 -- https://en.wikipedia.org/wiki/HarmonyOS (per rubric Instructions sheet: N/A, not 0, for platforms that did not yet exist) | K34: N/A | L34: Agreed independently by both raters; no reconciliation needed.
A35: HarmonyOS | B35: 2015 | C35: T1 | D35: Transparency | E35: Transparency of AI / data handling (what leaves the device) | F35: N/A | G35: HarmonyOS did not exist in 2015 (Huawei announced/launched it in August 2019, initially for smart-screen/TV devices only). Scored N/A per protocol, not 0, since 0 would incorrectly imply the platform existed but lacked the feature. | H35: M. Alhawarat | I35: N/A | J35: HarmonyOS publicly launched Aug 2019 (Huawei Developer Conference); did not exist in 2015 -- https://en.wikipedia.org/wiki/HarmonyOS (per rubric Instructions sheet: N/A, not 0, for platforms that did not yet exist) | K35: N/A | L35: Agreed independently by both raters; no reconciliation needed.
A36: HarmonyOS | B36: 2015 | C36: T2 | D36: Transparency | E36: User-facing privacy controls / permission granularity | F36: N/A | G36: HarmonyOS did not exist in 2015 (Huawei announced/launched it in August 2019, initially for smart-screen/TV devices only). Scored N/A per protocol, not 0, since 0 would incorrectly imply the platform existed but lacked the feature. | H36: M. Alhawarat | I36: N/A | J36: HarmonyOS publicly launched Aug 2019 (Huawei Developer Conference); did not exist in 2015 -- https://en.wikipedia.org/wiki/HarmonyOS (per rubric Instructions sheet: N/A, not 0, for platforms that did not yet exist) | K36: N/A | L36: Agreed independently by both raters; no reconciliation needed.
A37: HarmonyOS | B37: 2015 | C37: T3 | D37: Transparency | E37: Independent audit / compliance documentation | F37: N/A | G37: HarmonyOS did not exist in 2015 (Huawei announced/launched it in August 2019, initially for smart-screen/TV devices only). Scored N/A per protocol, not 0, since 0 would incorrectly imply the platform existed but lacked the feature. | H37: M. Alhawarat | I37: N/A | J37: HarmonyOS publicly launched Aug 2019 (Huawei Developer Conference); did not exist in 2015 -- https://en.wikipedia.org/wiki/HarmonyOS (per rubric Instructions sheet: N/A, not 0, for platforms that did not yet exist) | K37: N/A | L37: Agreed independently by both raters; no reconciliation needed.
A38: HarmonyOS | B38: 2020 | C38: A1 | D38: Authentication | E38: Biometric authentication | F38: N/A | G38: By end of 2020, HarmonyOS existed only as a smart-TV/IoT-device OS (HarmonyOS 1.0, launched Aug 2019); it did not become a full smartphone/consumer OS comparable to the other three platforms in this study until HarmonyOS 2.0 launched publicly for smartphones in June 2021. Scored N/A rather than assessed, since a meaningful comparison to Apple/iOS, Fuchsia, and Windows as general-purpose consumer platforms is not applicable at this time point. | H38: M. Alhawarat | I38: N/A | J38: Per reconciliation with co-author: HarmonyOS 2.0 was still developer-beta-only for smartphones at end of 2020 (beta started 16 Dec 2020, P40/Mate30/MatePad Pro only); public phone launch was 2 Jun 2021. Only shipped consumer product by end-2020 was the smart-TV/IoT HarmonyOS 1.0 line (Honor Vision, Aug 2019), not a general-purpose platform comparable to Apple/Windows. Rescored N/A (was previously scored) to match co-author's standard that a platform must be an evaluable, shipping general-purpose consumer OS for this comparison -- https://www.huaweicentral.com/harmonyos/amp/ | K38: N/A | L38: Agreed independently by both raters; no reconciliation needed.
A39: HarmonyOS | B39: 2020 | C39: A2 | D39: Authentication | E39: Multi-factor / two-factor authentication | F39: N/A | G39: By end of 2020, HarmonyOS existed only as a smart-TV/IoT-device OS (HarmonyOS 1.0, launched Aug 2019); it did not become a full smartphone/consumer OS comparable to the other three platforms in this study until HarmonyOS 2.0 launched publicly for smartphones in June 2021. Scored N/A rather than assessed, since a meaningful comparison to Apple/iOS, Fuchsia, and Windows as general-purpose consumer platforms is not applicable at this time point. | H39: M. Alhawarat | I39: N/A | J39: Per reconciliation with co-author: HarmonyOS 2.0 was still developer-beta-only for smartphones at end of 2020 (beta started 16 Dec 2020, P40/Mate30/MatePad Pro only); public phone launch was 2 Jun 2021. Only shipped consumer product by end-2020 was the smart-TV/IoT HarmonyOS 1.0 line (Honor Vision, Aug 2019), not a general-purpose platform comparable to Apple/Windows. Rescored N/A (was previously scored) to match co-author's standard that a platform must be an evaluable, shipping general-purpose consumer OS for this comparison -- https://www.huaweicentral.com/harmonyos/amp/ | K39: N/A | L39: Agreed independently by both raters; no reconciliation needed.
A40: HarmonyOS | B40: 2020 | C40: A3 | D40: Authentication | E40: Secure boot / verified boot / hardware root of trust | F40: N/A | G40: By end of 2020, HarmonyOS existed only as a smart-TV/IoT-device OS (HarmonyOS 1.0, launched Aug 2019); it did not become a full smartphone/consumer OS comparable to the other three platforms in this study until HarmonyOS 2.0 launched publicly for smartphones in June 2021. Scored N/A rather than assessed, since a meaningful comparison to Apple/iOS, Fuchsia, and Windows as general-purpose consumer platforms is not applicable at this time point. | H40: M. Alhawarat | I40: N/A | J40: Per reconciliation with co-author: HarmonyOS 2.0 was still developer-beta-only for smartphones at end of 2020 (beta started 16 Dec 2020, P40/Mate30/MatePad Pro only); public phone launch was 2 Jun 2021. Only shipped consumer product by end-2020 was the smart-TV/IoT HarmonyOS 1.0 line (Honor Vision, Aug 2019), not a general-purpose platform comparable to Apple/Windows. Rescored N/A (was previously scored) to match co-author's standard that a platform must be an evaluable, shipping general-purpose consumer OS for this comparison -- https://www.huaweicentral.com/harmonyos/amp/ | K40: N/A | L40: Agreed independently by both raters; no reconciliation needed.
... A46: HarmonyOS | B46: 2020 | C46: T3 | D46: Transparency | E46: Independent audit / compliance documentation | F46: N/A | G46: By end of 2020, HarmonyOS existed only as a smart-TV/IoT-device OS (HarmonyOS 1.0, launched Aug 2019); it did not become a full smartphone/consumer OS comparable to the other three platforms in this study until HarmonyOS 2.0 launched publicly for smartphones in June 2021. Scored N/A rather than assessed, since a meaningful comparison to Apple/iOS, Fuchsia, and Windows as general-purpose consumer platforms is not applicable at this time point. | H46: M. Alhawarat | I46: N/A | J46: Per reconciliation with co-author: HarmonyOS 2.0 was still developer-beta-only for smartphones at end of 2020 (beta started 16 Dec 2020, P40/Mate30/MatePad Pro only); public phone launch was 2 Jun 2021. Only shipped consumer product by end-2020 was the smart-TV/IoT HarmonyOS 1.0 line (Honor Vision, Aug 2019), not a general-purpose platform comparable to Apple/Windows. Rescored N/A (was previously scored) to match co-author's standard that a platform must be an evaluable, shipping general-purpose consumer OS for this comparison -- https://www.huaweicentral.com/harmonyos/amp/ | K46: N/A | L46: Agreed independently by both raters; no reconciliation needed.
A47: HarmonyOS | B47: 2025/26 | C47: A1 | D47: Authentication | E47: Biometric authentication | F47: 2 | G47: HarmonyOS (Next / 6.0) supports fingerprint and facial-recognition biometric authentication; the new Star Shield architecture (HarmonyOS 6, 2025) specifically enhances biometric-authentication integrity by coordinating on-device hardware (camera, GPS) and isolating authentication in a TEE. Source: Notebookcheck, "HarmonyOS 6 debuts with Star Shield security and AI agent support" (2025); Saint Augustine’s University security overview (2025). | H47: M. Alhawarat | I47: 2 | J47: DEV Community, 'Practical Application of Face Liveness Detection... in HarmonyOS Next' (developer technical article, API 12) -- https://dev.to/xun_wang_6384a403f9817c2/practical-application-of-face-liveness-detection-and-card-certificate-recognition-in-the-smart-ccj -- confirms face liveness detection remains a documented HarmonyOS NEXT capability; fingerprint auth continues per Huawei device documentation. | K47: 2 | L47: Agreed independently by both raters; no reconciliation needed.
A48: HarmonyOS | B48: 2025/26 | C48: A2 | D48: Authentication | E48: Multi-factor / two-factor authentication | F48: 2 | G48: Documented "identity authentication service" combines password + fingerprint + verification code (a triple-factor model); the permission system additionally gates AI-sensitive and biometric actions behind explicit authorization. Source: DEV Community, "Talk about those ‘super secure’ operations of HarmonyOS Next" (security architecture overview). | H48: M. Alhawarat | I48: 2 | J48: REVISED to 2 -- adopting co-author's primary source: HarmonyOS NEXT's 'identity authentication service' combines password + fingerprint + verification code (documented triple-factor model), with AI-sensitive/biometric actions gated behind explicit authorization. Source: DEV Community, 'Talk about those super secure operations of HarmonyOS Next' (per co-author). | K48: 2 | L48: Agreed independently by both raters; no reconciliation needed.
A49: HarmonyOS | B49: 2025/26 | C49: A3 | D49: Authentication | E49: Secure boot / verified boot / hardware root of trust | F49: 2 | G49: HarmonyOS employs a Trusted Execution Environment (TEE) and hardware-rooted trust via secure elements/security chips isolated from the kernel, supporting hardware-backed encryption keys and secure-boot processes that prevent unauthorized firmware modification. Source: Saint Augustine’s University, "HarmonyOS Security Unveiled" (2025); DarkNavy AVSS adversarial security evaluation of iOS/Android/HarmonyOS. | H49: M. Alhawarat | I49: 2 | J49: PPC Land / HuaweiCentral coverage of HarmonyOS NEXT launch (23 Oct 2024) and Star Shield security architecture unveiling (21 Jun 2024 beta) -- https://ppc.land/huawei-launches-harmonyos-next-a-complete-break-from-android-ecosystem-in-2024/ ; https://huaweicentral.com/huawei-unveils-harmonyos-next-star-shield-security-for-better-privacy-protection -- Star Shield architecture explicitly covers 'system security, kernel security' and continues hardware-rooted secure boot; Huawei, official certification page -- https://consumer.huawei.com/cn/privacy/certification/ : states HarmonyOS NEXT obtained CCRC EAL5+ certification (Jun 2024), described as the highest security certification level currently achievable for a domestic (China) OS, plus ISO/IEC 42001:2023 (AI management systems) certification for Huawei Device Co. confirms continued CC/CCRC-level kernel certification. | K49: 2 | L49: Agreed independently by both raters; no reconciliation needed.
A50: HarmonyOS | B50: 2025/26 | C50: D1 | D50: Data protection | E50: Encryption at rest (device/file-level) | F50: 2 | G50: File-level encryption using different keys for different contexts protects data at rest, with key management handled via the Secure Enclave/TEE isolated from the kernel; AES symmetric encryption documented for bulk data storage. Source: DarkNavy AVSS Report (kernel-level evaluation); DEV Community HarmonyOS Next security overview. | H50: M. Alhawarat | I50: 2 | J50: DEV Community, 'In-depth Analysis of the Security Assurance Mechanisms for Critical Asset Storage in HarmonyOS Next' -- https://dev.to/xun_wang_6384a403f9817c2/in-depth-analysis-of-the-security-assurance-mechanisms-for-critical-asset-storage-in-harmonyos-next-80f -- documents AES-256-GCM encryption for critical asset storage, keys cleared from memory immediately after use. | K50: 2 | L50: Agreed independently by both raters; no reconciliation needed.
A51: HarmonyOS | B51: 2025/26 | C51: D2 | D51: Data protection | E51: Encryption in transit / secure networking defaults | F51: 2 | G51: The Star Shield architecture introduces "encrypted sharing options" for cross-device data transfer, and RSA asymmetric encryption is documented for key exchange during transmission. Source: Harmony Developers, "HarmonyOS Next officially released" (2025); DEV Community security overview. | H51: M. Alhawarat | I51: 2 | J51: PPC Land / HuaweiCentral coverage of HarmonyOS NEXT launch (23 Oct 2024) and Star Shield security architecture unveiling (21 Jun 2024 beta) -- https://ppc.land/huawei-launches-harmonyos-next-a-complete-break-from-android-ecosystem-in-2024/ ; https://huaweicentral.com/huawei-unveils-harmonyos-next-star-shield-security-for-better-privacy-protection -- Star Shield 'initiates end-to-end data encryption when sharing files or other media content between multiple devices' and a hardware-level 'one key one password' mechanism per device; scope is cross-device sharing rather than general app network traffic, noted for caution. | K51: 2 | L51: Agreed independently by both raters; no reconciliation needed.
A52: HarmonyOS | B52: 2025/26 | C52: D3 | D52: Data protection | E52: On-device / private processing of sensitive data | F52: 1 | G52: New AI-specific permissions (ohos.permission.ACCESS_LLM, ohos.permission.SAVE_AI_RESULT), introduced in 2025, gate on-device AI-model access and require explicit developer declaration, but the extent to which AI/assistant (Xiaoyi) processing occurs on-device versus in Huawei cloud services is not comprehensively documented in the same way as a formal "private cloud compute" guarantee. Source: DEV Community, "A Deep Guide to HarmonyOS Next Permission Management" (2025). | H52: M. Alhawarat | I52: 1 | J52: PPC Land / HuaweiCentral coverage of HarmonyOS NEXT launch (23 Oct 2024) and Star Shield security architecture unveiling (21 Jun 2024 beta) -- https://ppc.land/huawei-launches-harmonyos-next-a-complete-break-from-android-ecosystem-in-2024/ ; https://huaweicentral.com/huawei-unveils-harmonyos-next-star-shield-security-for-better-privacy-protection -- HDC 2024 introduced 'Harmony Intelligence,' described as HarmonyOS NEXT's first integrated on-device AI capability, but no detailed public architecture document (comparable to Apple's Private Cloud Compute blog) describing what is processed on-device vs. cloud was found. | K52: 1 | L52: Agreed independently by both raters; no reconciliation needed.
A53: HarmonyOS | B53: 2025/26 | C53: T1 | D53: Transparency | E53: Transparency of AI / data handling (what leaves the device) | F53: 2 | G53: The 2025 permission system explicitly categorizes AI-sensitive permissions (a dedicated AI_SENSITIVE tier in the four-level Permission Grading 3.0 model) and Huawei’s developer guidelines mandate a "Transparency Principle" requiring custom permission dialogs that clearly explain to users why AI-related data access is needed. Source: DEV Community, "A Deep Guide to HarmonyOS Next Permission Management" (2025). | H53: M. Alhawarat | I53: 2 | J53: REVISED to 2 -- adopting co-author's primary source: HarmonyOS NEXT's Permission Grading 3.0 model has a dedicated AI_SENSITIVE permission tier, and Huawei's developer guidelines mandate a 'Transparency Principle' requiring custom permission dialogs that explain why AI-related data access is needed. Source: DEV Community, 'A Deep Guide to HarmonyOS Next Permission Management' (2025) (per co-author). | K53: 2 | L53: Agreed independently by both raters; no reconciliation needed.
A54: HarmonyOS | B54: 2025/26 | C54: T2 | D54: Transparency | E54: User-facing privacy controls / permission granularity | F54: 2 | G54: Permission Grading 3.0 defines four distinct sensitivity tiers (Basic / Restricted / System-level / AI-sensitive) with per-permission, per-context enforcement; Star Shield is reported to have blocked over 8.6 billion "unreasonable" app permission requests across HarmonyOS’s history, indicating active, fine-grained enforcement rather than a nominal policy. Source: DEV Community permission-management guide (2025); Notebookcheck HarmonyOS 6 coverage (2025). | H54: M. Alhawarat | I54: 2 | J54: PPC Land / HuaweiCentral coverage of HarmonyOS NEXT launch (23 Oct 2024) and Star Shield security architecture unveiling (21 Jun 2024 beta) -- https://ppc.land/huawei-launches-harmonyos-next-a-complete-break-from-android-ecosystem-in-2024/ ; https://huaweicentral.com/huawei-unveils-harmonyos-next-star-shield-security-for-better-privacy-protection -- Star Shield 'restricts 9 types of unreasonable permissions,' including reading the list of installed apps, accessing SMS, accessing storage, and creating home-screen shortcuts without cause. | K54: 2 | L54: Agreed independently by both raters; no reconciliation needed.
A55: HarmonyOS | B55: 2025/26 | C55: T3 | D55: Transparency | E55: Independent audit / compliance documentation | F55: 1 | G55: Independent third-party security research exists — notably DarkNavy’s adversarial security evaluation (AVSS Report) comparing iOS, Android, and HarmonyOS NEXT at the kernel level — but this is independent security research rather than a formal, recognized compliance certification (e.g., ISO/IEC 27001, SOC 2) of the kind documented for Apple or Microsoft’s platforms. Source: DarkNavy, "AVSS Report: System Security Adversarial Capability... of iOS, Android, and HarmonyOS" (2025). | H55: M. Alhawarat | I55: 2 | J55: KEPT AT 2 -- this rests on a genuine formal certification (Huawei's official cert page: CCRC EAL5+, Jun 2024, plus ISO/IEC 42001:2023), which meets co-author's own stated bar for a '2' (formal, recognized compliance certification, as distinct from independent research). Co-author's file scores this a 1 citing DarkNavy's independent security research instead -- worth sharing this certification source with them, since it looks like a stronger match to their own standard than what they had on hand -- https://consumer.huawei.com/cn/privacy/certification/ | K55: 2 | L55: RECONCILED (was 1/2): Huawei holds formal CCRC EAL5+ (Jun 2024) and ISO/IEC 42001:2023 certifications -- genuine formal compliance certifications meeting the criterion's own bar for a 2, stronger than the DarkNavy independent-research citation originally used.
A56: Fuchsia | B56: 2015 | C56: A1 | D56: Authentication | E56: Biometric authentication | F56: N/A | G56: Fuchsia did not exist in 2015; its first public code appeared on GitHub in August 2016. Scored N/A per protocol, not 0. | H56: M. Alhawarat | I56: N/A | J56: Fuchsia's source code was first published by Google in August 2016 (no corporate announcement); did not exist in 2015 -- https://en.wikipedia.org/wiki/Fuchsia_(operating_system) (per rubric Instructions sheet: N/A, not 0, for platforms that did not yet exist) | K56: N/A | L56: Agreed independently by both raters; no reconciliation needed.
A57: Fuchsia | B57: 2015 | C57: A2 | D57: Authentication | E57: Multi-factor / two-factor authentication | F57: N/A | G57: Fuchsia did not exist in 2015; its first public code appeared on GitHub in August 2016. Scored N/A per protocol, not 0. | H57: M. Alhawarat | I57: N/A | J57: Fuchsia's source code was first published by Google in August 2016 (no corporate announcement); did not exist in 2015 -- https://en.wikipedia.org/wiki/Fuchsia_(operating_system) (per rubric Instructions sheet: N/A, not 0, for platforms that did not yet exist) | K57: N/A | L57: Agreed independently by both raters; no reconciliation needed.
A58: Fuchsia | B58: 2015 | C58: A3 | D58: Authentication | E58: Secure boot / verified boot / hardware root of trust | F58: N/A | G58: Fuchsia did not exist in 2015; its first public code appeared on GitHub in August 2016. Scored N/A per protocol, not 0. | H58: M. Alhawarat | I58: N/A | J58: Fuchsia's source code was first published by Google in August 2016 (no corporate announcement); did not exist in 2015 -- https://en.wikipedia.org/wiki/Fuchsia_(operating_system) (per rubric Instructions sheet: N/A, not 0, for platforms that did not yet exist) | K58: N/A | L58: Agreed independently by both raters; no reconciliation needed.
A59: Fuchsia | B59: 2015 | C59: D1 | D59: Data protection | E59: Encryption at rest (device/file-level) | F59: N/A | G59: Fuchsia did not exist in 2015; its first public code appeared on GitHub in August 2016. Scored N/A per protocol, not 0. | H59: M. Alhawarat | I59: N/A | J59: Fuchsia's source code was first published by Google in August 2016 (no corporate announcement); did not exist in 2015 -- https://en.wikipedia.org/wiki/Fuchsia_(operating_system) (per rubric Instructions sheet: N/A, not 0, for platforms that did not yet exist) | K59: N/A | L59: Agreed independently by both raters; no reconciliation needed.
...

Sheet Trend
A1: Security / Privacy Posture by Platform and Time Point (auto-calculated from Scoring sheet)
A3: Platform | B3: 2015 Total | C3: 2015 Scored (n) | D3: 2015 Avg /2 | E3: 2020 Total | F3: 2020 Scored (n) | G3: 2020 Avg /2 | H3: 2025/26 Total | I3: 2025/26 Scored (n) | J3: 2025/26 Avg /2
A4: Apple / iOS | B4: =SUMIFS(Scoring!$K$2:$K$109,Scoring!$A$2:$A$109,$A4,Scoring!$B$2:$B$109,"2015") -> 12 | C4: =COUNTIFS(Scoring!$A$2:$A$109,$A4,Scoring!$B$2:$B$109,"2015",Scoring!$K$2:$K$109,"<>N/A",Scoring!$K$2:$K$109,"<>") -> 9 | D4: =IFERROR(B4/(C4*2),"-") -> 0.66666667 | E4: =SUMIFS(Scoring!$K$2:$K$109,Scoring!$A$2:$A$109,$A4,Scoring!$B$2:$B$109,"2020") -> 16 | F4: =COUNTIFS(Scoring!$A$2:$A$109,$A4,Scoring!$B$2:$B$109,"2020",Scoring!$K$2:$K$109,"<>N/A",Scoring!$K$2:$K$109,"<>") -> 9 | G4: =IFERROR(E4/(F4*2),"-") -> 0.88888889 | H4: =SUMIFS(Scoring!$K$2:$K$109,Scoring!$A$2:$A$109,$A4,Scoring!$B$2:$B$109,"2025/26") -> 18 | I4: =COUNTIFS(Scoring!$A$2:$A$109,$A4,Scoring!$B$2:$B$109,"2025/26",Scoring!$K$2:$K$109,"<>N/A",Scoring!$K$2:$K$109,"<>") -> 9 | J4: =IFERROR(H4/(I4*2),"-") -> 1
A5: HarmonyOS | B5: =SUMIFS(Scoring!$K$2:$K$109,Scoring!$A$2:$A$109,$A5,Scoring!$B$2:$B$109,"2015") -> 0 | C5: =COUNTIFS(Scoring!$A$2:$A$109,$A5,Scoring!$B$2:$B$109,"2015",Scoring!$K$2:$K$109,"<>N/A",Scoring!$K$2:$K$109,"<>") -> 0 | D5: =IFERROR(B5/(C5*2),"-") -> - | E5: =SUMIFS(Scoring!$K$2:$K$109,Scoring!$A$2:$A$109,$A5,Scoring!$B$2:$B$109,"2020") -> 0 | F5: =COUNTIFS(Scoring!$A$2:$A$109,$A5,Scoring!$B$2:$B$109,"2020",Scoring!$K$2:$K$109,"<>N/A",Scoring!$K$2:$K$109,"<>") -> 0 | G5: =IFERROR(E5/(F5*2),"-") -> - | H5: =SUMIFS(Scoring!$K$2:$K$109,Scoring!$A$2:$A$109,$A5,Scoring!$B$2:$B$109,"2025/26") -> 17 | I5: =COUNTIFS(Scoring!$A$2:$A$109,$A5,Scoring!$B$2:$B$109,"2025/26",Scoring!$K$2:$K$109,"<>N/A",Scoring!$K$2:$K$109,"<>") -> 9 | J5: =IFERROR(H5/(I5*2),"-") -> 0.94444444
A6: Fuchsia | B6: =SUMIFS(Scoring!$K$2:$K$109,Scoring!$A$2:$A$109,$A6,Scoring!$B$2:$B$109,"2015") -> 0 | C6: =COUNTIFS(Scoring!$A$2:$A$109,$A6,Scoring!$B$2:$B$109,"2015",Scoring!$K$2:$K$109,"<>N/A",Scoring!$K$2:$K$109,"<>") -> 0 | D6: =IFERROR(B6/(C6*2),"-") -> - | E6: =SUMIFS(Scoring!$K$2:$K$109,Scoring!$A$2:$A$109,$A6,Scoring!$B$2:$B$109,"2020") -> 0 | F6: =COUNTIFS(Scoring!$A$2:$A$109,$A6,Scoring!$B$2:$B$109,"2020",Scoring!$K$2:$K$109,"<>N/A",Scoring!$K$2:$K$109,"<>") -> 0 | G6: =IFERROR(E6/(F6*2),"-") -> - | H6: =SUMIFS(Scoring!$K$2:$K$109,Scoring!$A$2:$A$109,$A6,Scoring!$B$2:$B$109,"2025/26") -> 8 | I6: =COUNTIFS(Scoring!$A$2:$A$109,$A6,Scoring!$B$2:$B$109,"2025/26",Scoring!$K$2:$K$109,"<>N/A",Scoring!$K$2:$K$109,"<>") -> 9 | J6: =IFERROR(H6/(I6*2),"-") -> 0.44444444
A7: Windows | B7: =SUMIFS(Scoring!$K$2:$K$109,Scoring!$A$2:$A$109,$A7,Scoring!$B$2:$B$109,"2015") -> 10 | C7: =COUNTIFS(Scoring!$A$2:$A$109,$A7,Scoring!$B$2:$B$109,"2015",Scoring!$K$2:$K$109,"<>N/A",Scoring!$K$2:$K$109,"<>") -> 9 | D7: =IFERROR(B7/(C7*2),"-") -> 0.55555556 | E7: =SUMIFS(Scoring!$K$2:$K$109,Scoring!$A$2:$A$109,$A7,Scoring!$B$2:$B$109,"2020") -> 16 | F7: =COUNTIFS(Scoring!$A$2:$A$109,$A7,Scoring!$B$2:$B$109,"2020",Scoring!$K$2:$K$109,"<>N/A",Scoring!$K$2:$K$109,"<>") -> 9 | G7: =IFERROR(E7/(F7*2),"-") -> 0.88888889 | H7: =SUMIFS(Scoring!$K$2:$K$109,Scoring!$A$2:$A$109,$A7,Scoring!$B$2:$B$109,"2025/26") -> 17 | I7: =COUNTIFS(Scoring!$A$2:$A$109,$A7,Scoring!$B$2:$B$109,"2025/26",Scoring!$K$2:$K$109,"<>N/A",Scoring!$K$2:$K$109,"<>") -> 9 | J7: =IFERROR(H7/(I7*2),"-") -> 0.94444444
A9: Total = sum of 0/1/2 scores for that platform and time point. Scored (n) = number of criteria actually scored (N/A and blanks excluded). Avg /2 = Total / (Scored × 2), i.e., posture as a percentage of the maximum possible. N/A cells (platform did not exist) are excluded so early time points are not unfairly penalized.
