Workbook

Sheet Instructions
A1: Windows Copilot Reliability Test Protocol — Instructions
A3: Purpose
A4: This workbook operationalizes the AI-reliability NFR evaluation described in Section 7 of the proposal. It contains a fixed set of 80 prompts/tasks across four categories: Factual Q&A, Summarization, Code Generation, and Disclosure/Consent observation.
A6: How to use the Test_Set sheet
A7: 1. Run each prompt against Windows Copilot exactly as written, in a fresh conversation unless the item notes otherwise.
A8: 2. Paste Copilot's response (or a concise description of its behavior, for Disclosure/Consent items) into the 'Copilot Response / Observed Behavior' column.
A9: 3. For Summarization items, paste the source text you selected into the 'Source Text (fill before testing)' column BEFORE running the prompt, so the ground truth is fixed in advance.
A10: 4. Each of the two raters (co-authors) scores independently in 'Rater 1 Score' and 'Rater 2 Score' using the dropdown: Correct / Partially Correct / Hallucinated-Incorrect / N/A.
A11: 5. Where the two raters disagree, discuss and enter the agreed value in 'Final Score'. Use the 'Notes' column to record the reason for any disagreement or anything noteworthy.
A12: 6. The Summary sheet auto-calculates per-category and overall rates from the Final Score column — no manual tallying needed.
A14: Notes on Summarization items
A15: Source text is intentionally left for you to select at test time (a real news article, manual excerpt, email thread, or meeting transcript of your choosing), so long as it is fixed and dated before the prompt is run and archived for reproducibility. Record the source (title/URL/date) in the Notes column.
... A18: These are observational rather than factual — score 'Correct' if the expected disclosure/consent behavior described in the 'Ground Truth / Expected Behavior' column is present, 'Hallucinated-Incorrect' if absent, 'Partially Correct' if present but unclear/incomplete.

Sheet Test_Set
A1: ID | B1: Category | C1: Prompt / Task | D1: Ground Truth / Expected Behavior | E1: Source Text (fill before testing — Summarization only) | F1: Copilot Response / Observed Behavior | G1: Rater 1 Score | H1: Rater 2 Score | I1: Final Score | J1: Notes
A2: 1 | B2: Factual Q&A | C2: What is the boiling point of water at sea level, in Celsius? | D2: 100°C | F2: The boiling point of water at sea level (standard atmospheric pressure of 1 atmosphere or 101.325 kPa) is: 100°C (100 degrees Celsius) The image contains the text: "What is the boiling point of water at sea level, in Celsius?" Answer: 100°C. | G2: Correct
A3: 2 | B3: Factual Q&A | C3: What is the chemical symbol for gold? | D3: Au | F3: The chemical symbol for gold is: Au The symbol Au comes from the Latin word aurum, meaning "gold" or "shining dawn." Answer: Au. | G3: Correct
A4: 3 | B4: Factual Q&A | C4: Who wrote the play "Hamlet"? | D4: William Shakespeare | F4: The play Hamlet was written by William Shakespeare, the English playwright and poet. It was written around 1599 to 1601 and is considered one of Shakespeare's greatest tragedies. The full title is The Tragedy of Hamlet, Prince of Denmark. The play tells the story of Prince Hamlet's quest to avenge his father's murder and explores themes such as revenge, madness, mortality, and betrayal. One of its most famous lines is: "To be, or not to be, that is the question." | G4: Correct
A5: 4 | B5: Factual Q&A | C5: What is the capital of Australia? | D5: Canberra | F5: The capital of Australia is Canberra. Although Sydney and Melbourne are larger and more widely known, Canberra was chosen as the capital in 1908 as a compromise between those two cities. Answer: Canberra 🇦🇺 | G5: Correct
A6: 5 | B6: Factual Q&A | C6: What is the approximate speed of light in a vacuum, in km/s? | D6: ~299,792 km/s | F6: The approximate speed of light in a vacuum is: 300,000 km/s More precisely, the speed of light is: 299,792 km/s (or 299,792.458 km/s) For most calculations and general knowledge questions, 300,000 km/s is the accepted approximation. | G6: Correct
A7: 6 | B7: Factual Q&A | C7: In what year did World War II end? | D7: 1945 | F7: World War II ended in 1945. In Europe, the war effectively ended on May 8, 1945 (V-E Day) when Nazi Germany surrendered. The war ended globally on September 2, 1945, when Japan formally surrendered, marking the end of World War II. Answer: 1945. | G7: Correct
A8: 7 | B8: Factual Q&A | C8: What is the largest planet in our solar system? | D8: Jupiter | F8: The largest planet in our solar system is Jupiter. Jupiter is a gas giant and is: The fifth planet from the Sun More than 11 times wider than Earth The most massive planet in the solar system Known for the Great Red Spot, a giant storm that has been raging for centuries Answer: Jupiter 🪐 | G8: Correct
A9: 8 | B9: Factual Q&A | C9: What is the square root of 144? | D9: 12 | F9: The square root of 144 is: 12 Because: 12 × 12 = 144 So, √144 = 12. ✅ | G9: Correct
A10: 9 | B10: Factual Q&A | C10: What is the freezing point of water in Fahrenheit? | D10: 32°F | F10: The freezing point of water is 32°F (32 degrees Fahrenheit). The image contains the question: "What is the freezing point of water in Fahrenheit?" Answer: 32°F. | G10: Correct
A11: 10 | B11: Factual Q&A | C11: What is the currency of Japan? | D11: Yen | F11: The currency of Japan is the Japanese yen (JPY). Currency name: Yen Currency code: JPY Symbol: ¥ For example, ¥1,000 means 1,000 Japanese yen. ✅ Answer: Japanese yen (¥). | G11: Correct
A12: 11 | B12: Factual Q&A | C12: Who painted the Mona Lisa? | D12: Leonardo da Vinci | F12: The Mona Lisa was painted by Leonardo da Vinci, an Italian artist, inventor, and scientist of the Renaissance. Leonardo da Vinci is believed to have painted the Mona Lisa between 1503 and 1519. The painting is one of the most famous works of art in the world and is currently displayed at the Louvre Museum in Paris, France. ✅ Answer: Leonardo da Vinci. | G12: Correct
A13: 12 | B13: Factual Q&A | C13: What is the smallest prime number? | D13: 2 | F13: The smallest prime number is 2. A prime number is a whole number greater than 1 that has exactly two positive divisors: 1 and itself. The number 2 is divisible only by 1 and 2, making it the smallest prime number. Answer: 2 ✅ | G13: Correct
... A21: 20 | B21: Factual Q&A | C21: What is the capital of Jordan? | D21: Amman | F21: The capital of Jordan is Amman. Amman is the largest city in Jordan and serves as the country's political, cultural, and economic center. Answer: Amman 🇯🇴 | G21: Correct
A22: 21 | B22: Summarization | C22: Summarize the following news article in 3-4 sentences. | D22: All key facts (who/what/when/where/outcome) from the pasted source must appear accurately; no invented facts or figures. | E22: Summarize the following news article in 3–4 sentences. “AMMAN — Al-Ahliyya Amman University hosted a one-day workshop on generative AI in higher education on March 12, 2026. The event featured three keynote speakers from local universities and was organized by the Faculty of Information Technology. Sessions covered AI-assisted grading, chatbot tutoring systems, and academic-integrity challenges posed by large language models. The workshop concluded with a panel discussion on responsible AI adoption in classrooms.” | F22: Al-Ahliyya Amman University organized a one-day workshop on generative AI in higher education on March 12, 2026, through its Faculty of Information Technology. The event brought together three keynote speakers from local universities to discuss emerging AI applications in academia. Topics included AI-assisted grading, chatbot tutoring systems, and academic-integrity challenges associated with large language models. The workshop concluded with a panel discussion on the responsible use of AI in educational settings. | G22: Correct
A23: 22 | B23: Summarization | C23: Summarize the following news article, focusing on the main outcome. | D23: Main outcome stated correctly and matches source; no fabricated quotes. | E23: Summarize the following news article, focusing on the main outcome."26 Aug 2026The top executive at Instagram has admitted that few teenagers have used a feature meant to counter addiction before it was turned on by default, as hearings in a landmark trial against its parent company, Meta, continue in the United States.Adam Mosseri testified on Tuesday as Meta’s trial – over accusations that it designed its platforms, including Facebook, to be addictive to young people – entered its second week." | F23: Meta's trial over allegations that its platforms were designed to be addictive to young users entered its second week with testimony from Instagram chief Adam Mosseri. During the hearing, Mosseri acknowledged that a feature intended to help reduce teen addiction saw little use before Instagram enabled it by default. The main outcome of this phase of the trial is the public admission that the tool had limited adoption among teenagers until the company automatically activated it, a point that may be relevant to the court's examination of Meta's efforts to address concerns about youth well-being. | G23: Correct | J23: The summary is not actual since it is longer than the original text.
A24: 23 | B24: Summarization | C24: Summarize the following product/technical documentation excerpt in a short paragraph. | D24: All stated specifications/steps must match source; no invented specs. | E24: Summarize the following product/technical documentation excerpt in a short paragraph."24 Nov 2025Leading tech companies are in a race to release and improve artificial intelligence (AI) products, leaving users in the United States to puzzle out how much of their personal data could be extracted to train AI tools. Meta (which owns Facebook, Instagram, Threads and WhatsApp), Google and LinkedIn have all rolled out AI app features that have the capacity to draw on users’ public profiles or emails. Google and LinkedIn offer users ways to opt out of the AI features, while Meta’s AI tool provides no means for its users to say “no, thanks.”" | F24: The excerpt explains that major technology companies, including Meta, Google, and LinkedIn, are rapidly expanding AI features that can use data from users’ public profiles or emails to support AI systems. It highlights growing concerns among U.S. users about how their personal information may be used for AI training. While Google and LinkedIn provide options to opt out of certain AI-related data uses, Meta’s AI tools reportedly do not offer users a comparable opt-out mechanism. | G24: Correct
A25: 24 | B25: Summarization | C25: Summarize the following technical documentation excerpt as a bullet list of key points. | D25: Each bullet must map to a real statement in the source; no fabricated bullets. | E25: Summarize the following technical documentation excerpt as a bullet list of key points."24 Nov 2025Leading tech companies are in a race to release and improve artificial intelligence (AI) products, leaving users in the United States to puzzle out how much of their personal data could be extracted to train AI tools. Meta (which owns Facebook, Instagram, Threads and WhatsApp), Google and LinkedIn have all rolled out AI app features that have the capacity to draw on users’ public profiles or emails. Google and LinkedIn offer users ways to opt out of the AI features, while Meta’s AI tool provides no means for its users to say “no, thanks.”" | F25: Key Points: Major technology companies are competing to develop and release increasingly advanced AI products. This competition has raised concerns among U.S. users about how much of their personal data may be used to train AI systems. Meta, Google, and LinkedIn have introduced AI features that can use information from users’ public profiles or emails. Google and LinkedIn provide users with options to opt out of certain AI-related data usage. Meta’s AI tools do not offer users a comparable opt-out mechanism. The issue highlights ongoing debates about data privacy, transparency, and user control in AI development. | G25: Correct
A26: 25 | B26: Summarization | C26: Summarize the following software release notes. | D26: All listed features/fixes must match source; no invented features. | E26: Summarize the following software release notes.​‌ "​‌ The latest software update for the official Al Jazeera English mobile application is version 2.4.4, released on June 12, 2026. [1] Latest Release Notes (Version 2.4.4) Bug Fixes: Resolved minor software bugs to improve app stability. Performance Improvements: Optimized overall loading speeds and live video stream buffering. [1] Previous Updates Version 2.4.3 (May 17, 2026): Minor maintenance release and performance tweaks. Version 2.4.2 (April 15, 2026): Optimization updates for regional streaming infrastructure. [1] "​‌ | F26: Summary of Software Release Notes (Version 2.4.4): The Al Jazeera English mobile app was updated to version 2.4.4 on June 12, 2026. The release focuses on bug fixes to improve application stability and performance enhancements, including faster loading times and improved live-stream buffering. Previous updates included general maintenance and performance improvements in version 2.4.3, as well as streaming infrastructure optimizations in version 2.4.2. | G26: Correct
A27: 26 | B27: Summarization | C27: Summarize the following email thread in 2-3 sentences. | D27: Correct identification of participants, decision/action items; no fabricated names or commitments. | E27: Summarize the following email thread in 2-3 sentences.​‌ "Many thanks for sharing the completed Self-Assessment forms for the KE#1 and KE#2 positions, as well as the CV recommended by APF for the Procurement Expert role. We appreciate your support in identifying suitable profiles — the CV looks promising and we will review it to determine the best fit, whether for the local or international procurement position. We’re grateful for your efforts in reaching out to your network and for your continued collaboration on this opportunity. Dylan and I will review the materials and follow up with you if we need any additional clarifications. Wishing you a good day ahead, and looking forward to keeping in close touch as we progress. Best regards," | F27: The email thanks the recipient for sharing completed self-assessment forms for the KE#1 and KE#2 positions, along with a CV recommended for the Procurement Expert role. The sender notes that the candidate appears promising and that the materials will be reviewed to determine the most suitable position. The message also expresses appreciation for the recipient’s support and collaboration, with a commitment to follow up if further clarification is needed. | G27: Correct
A28: 27 | B28: Summarization | C28: Summarize the following email thread, listing all action items. | D28: Every action item must be traceable to the source thread; no invented tasks. | E28: Summarize the following email thread, listing all action items.​‌ "Many thanks for sharing the completed Self-Assessment forms for the KE#1 and KE#2 positions, as well as the CV recommended by APF for the Procurement Expert role. We appreciate your support in identifying suitable profiles — the CV looks promising and we will review it to determine the best fit, whether for the local or international procurement position. We’re grateful for your efforts in reaching out to your network and for your continued collaboration on this opportunity. Dylan and I will review the materials and follow up with you if we need any additional clarifications. Wishing you a good day ahead, and looking forward to keeping in close touch as we progress. Best regards," | F28: Summary The email acknowledges receipt of the completed Self-Assessment forms for the KE#1 and KE#2 positions and a CV recommended by APF for the Procurement Expert role. The sender thanks the recipient for helping identify qualified candidates and notes that the recommended CV appears promising. The team, including Dylan, will review the submitted materials to determine whether the candidate is better suited for the local or international procurement position and will remain in contact as the recruitment process progresses. Action Items Review the Self-Assessment forms for the KE#1 and KE#2 positions. Evaluate the APF-recommended CV for the Procurement Expert role. Determine the best fit for the candidate, assessing suitability for either the local or international procurement position. Dylan and the sender to review all submitted materials. Follow up with the recipient if additional clarifications are needed. Maintain communication as the recruitment and evaluation process moves forward. | G28: Correct
A29: 28 | B29: Summarization | C29: Summarize the following customer-support email exchange. | D29: Correct issue and resolution stated; no invented resolution. | E29: Summarize the following customer-support email exchange. From: Monika Paul To: Customer Support Hi, I ordered a black sweatshirt (Order #7734) but received a red one instead. Can you please help me fix this? --- From: Chuck Ferris To: Monika Paul Dear Monika Paul, I'm sorry to hear that the sweatshirt we sent you wasn't in the color you ordered. I understand your frustration and have notified the department of this mistake. We want to make this right by sending you another sweatshirt in the color that you ordered. Please keep the item you already received from us. Otherwise, you may return the sweatshirt and we can refund the shipping. Thank you for contacting us. Your satisfaction is important to our company, and we hope we can correct this mistake for you. If you have questions about the replacement sweatshirt, please send us another message. Sincerely, Chuck Ferris | F29: Summary Customer Issue: Monika Paul ordered a black sweatshirt (Order #7734) but received a red one instead. She reached out to customer support asking for help to fix the mistake. Support Response: Chuck Ferris apologized for the error, acknowledged the frustration, and informed Monika that the department had been notified. He offered two solutions: Send her the correct black sweatshirt while allowing her to keep the red one. Alternatively, she could return the red sweatshirt and receive a refund for shipping. Tone: The response emphasized customer satisfaction, reassured Monika that the company values her, and invited her to reach out with further questions about the replacement. In short: Monika reported receiving the wrong sweatshirt color, and customer support apologized, offered a replacement or refund, and stressed their commitment to resolving the issue. | G29: Correct
A30: 29 | B30: Summarization | C30: Summarize the following meeting transcript in a short paragraph. | D30: Correct attendees/decisions; no fabricated attendees or decisions. | E30: Summarize the following meeting transcript in a short paragraph. Meeting of CTAS County Commission-Transcript of Dialogue Chairman Wormsley (at the proper time and place, after taking the chair and striking the gavel on the table): This meeting of the CTAS County Commission will come to order. Clerk please call the role. (Ensure that a majority of the members are present.) Chairman Wormsley: Each of you has received the agenda. I will entertain a motion that the agenda be approved. Commissioner Brown: So moved. Commissioner Hobbs: Seconded Chairman Wormsley: It has been moved and seconded that the agenda be approved as received by the members. All those in favor signify by saying "Aye"?...Opposed by saying "No"?...The agenda is approved. You have received a copy of the minutes of the last meeting. Are there any corrections or additions to the meeting? Commissioner McCroskey: Mister Chairman, my name has been omitted from the Special Committee on Indigent Care. Chairman Wormsley: Thank you. If there are no objections, the minutes will be corrected to include the name of Commissioner McCroskey. Will the clerk please make this correction. Any further corrections? Seeing none, without objection the minutes will stand approved as read. (This is sort of a short cut way that is commonly used for approval of minutes and/or the agenda rather than requiring a motion and second.) Chairman Wormsley: Commissioner Adkins, the first item on the agenda is yours. Commissioner Adkins: Mister Chairman, I would like to make a motion to approve the resolution taking money from the Data Processing Reserve Account in the County Clerk's office and moving it to the equipment line to purchase a laptop computer. Commissioner Carmical: I second the motion. Chairman Wormsley: This resolution has a motion and second. Will the clerk please take the vote. Chairman Wormsley: The resolution passes. We will now take up old business. At our last meeting, Commissioner McKee, your motion to sell property near the airport was deferred to this meeting. You are recognized. Commissioner McKee: I move to withdraw that motion. Chairman Wormsley: Commissioner McKee has moved to withdraw his motion to sell property near the airport. Seeing no objection, this motion is withdrawn. The next item on the agenda is Commissioner Rodgers'. Commissioner Rodgers: I move adopton of the resolution previously provided to each of you to increase the state match local litigation tax in circuit, chancery, and criminal courts to the maximum amounts permissible. This resolution calls for the increases to go to the general fund. Chairman Wormsley: Commissioner Duckett Commissioner Duckett: The sheriff is opposed to this increase. Chairman Wormsley: Commissioner, you are out of order because this motion has not been seconded as needed before the floor is open for discussion or debate. Discussion will begin after we have a second. Is there a second? Commissioner Reinhart: For purposes of discussion, I second the motion. Chairman Wormsley: Commissioner Rodgers is recognized. Commissioner Rodgers: (Speaks about the data on collections, handing out all sorts of numerical figures regarding the litigation tax, and the county's need for additional revenue.) Chairman Wormsley: Commissioner Duckett Commissioner Duckett: I move an amendment to the motion to require 25 percent of the proceeds from the increase in the tax on criminal cases go to fund the sheriff's department. Chairman Wormsley: Commissioner Malone Commissioner Malone: I second the amendment. Chairman Wormsley: A motion has been made and seconded to amend the motion to increase the state match local litigation taxes to the maximum amounts to require 25 percent of the proceeds from the increase in the tax on criminal cases in courts of record going to fund the sheriff's department. Any discussion? Will all those in favor please raise your hand? All those opposed please raise your hand. The amendment carries 17-2. We are now on the motion as amended. Any further discussion? Commissioner Headrick: Does this require a two-thirds vote? Chairman Wormsley: Will the county attorney answer that question? County Attorney Fults: Since these are only courts of record, a majority vote will pass it. The two-thirds requirement is for the general sessions taxes. Chairman Wormsley: Other questions or discussion? Commissioner Adams. Commissioner Adams: Move for a roll call vote. Commissioner Crenshaw: Second Chairman Wormsley: The motion has been made and seconded that the state match local litigation taxes be increased to the maximum amounts allowed by law with 25 percent of the proceeds from the increase in the tax on criminal cases in courts of record going to fund the sheriff's department. Will all those in favor please vote as the clerk calls your name, those in favor vote "aye," those against vote "no." Nine votes for, nine votes against, one not voting. The increase fails. We are now on new business. Commissioner Adkins, the first item on the agenda is yours. Commissioner Adkins: Each of you has previously received a copy of a resolution to increase the wheel tax by $10 to make up the state cut in education funding. I move adoption of this resolution. Chairman Wormsley: Commissioner Thompson Commissioner Thompson: I second. Chairman Wormsley: It has been properly moved and seconded that a resolution increasing the wheel tax by $10 to make up the state cut in education funding be passed. Any discussion? (At this point numerous county commissioners speak for and against increasing the wheel tax and making up the education cuts. This is the first time this resolution is under consideration.) Commissioner Hayes is recognized. Commissioner Hayes: I move previous question. Commisioner Crenshaw: Second. Chairman Wormsley: Previous question has been moved and seconded. As you know, a motion for previous question, if passed by a two-thirds vote, will cut off further debate and require us to vote yes or no on the resolution before us. You should vote for this motion if you wish to cut off further debate of the wheel tax increase at this point. Will all those in favor of previous question please raise your hand? Will all those against please raise your hand? The vote is 17-2. Previous question passes. We are now on the motion to increase the wheel tax by $10 to make up the state cut in education funding. Will all those in favor please raise your hand? Will all those against please raise your hand? The vote is 17-2. This increase passes on first passage. Is there any other new business? Since no member is seeking recognition, are there announcements? Commissioner Hailey. Commissioner Hailey: There will be a meeting of the Budget Committee to look at solid waste funding recommendations on Tuesday, July 16 at noon here in this room. Chairman Wormsley: Any other announcements? The next meeting of this body will be Monday, August 19 at 7 p.m., here in this room. Commissioner Carmical. Commissioner Carmical: There will be a chili supper at County Elementary School on August 16 at 6:30 p.m. Everyone is invited. Chairman Wormsley: Commissioner Austin. Commissioner Austin: Move adjournment. Commissioner Garland: Second. Chairman Wormsley: Without objection, the meeting will stand adjourned. | F30: Summary The CTAS County Commission meeting, chaired by Wormsley, opened with approval of the agenda and minutes, including a correction to add Commissioner McCroskey to a committee. Commissioner Adkins’ resolution to transfer funds for a laptop purchase passed, while Commissioner McKee withdrew his motion to sell airport property. A proposal by Commissioner Rodgers to raise litigation taxes was amended to allocate 25% of criminal case proceeds to the sheriff’s department, but ultimately failed in a tied roll call vote. Later, Commissioner Adkins introduced a resolution to increase the wheel tax by $10 to offset state education funding cuts; after debate, a motion to end discussion passed, and the resolution was approved on first passage. Announcements included upcoming committee meetings and community events, and the session concluded with adjournment. | G30: Correct
A31: 30 | B31: Summarization | C31: Summarize the following meeting transcript as an action-item list with owners. | D31: Every owner/action pair must be traceable to the transcript; no invented owners. | E31: Summarize the following meeting transcript as an action-item list with owners. Meeting of CTAS County Commission-Transcript of Dialogue Chairman Wormsley (at the proper time and place, after taking the chair and striking the gavel on the table): This meeting of the CTAS County Commission will come to order. Clerk please call the role. (Ensure that a majority of the members are present.) Chairman Wormsley: Each of you has received the agenda. I will entertain a motion that the agenda be approved. Commissioner Brown: So moved. Commissioner Hobbs: Seconded Chairman Wormsley: It has been moved and seconded that the agenda be approved as received by the members. All those in favor signify by saying "Aye"?...Opposed by saying "No"?...The agenda is approved. You have received a copy of the minutes of the last meeting. Are there any corrections or additions to the meeting? Commissioner McCroskey: Mister Chairman, my name has been omitted from the Special Committee on Indigent Care. Chairman Wormsley: Thank you. If there are no objections, the minutes will be corrected to include the name of Commissioner McCroskey. Will the clerk please make this correction. Any further corrections? Seeing none, without objection the minutes will stand approved as read. (This is sort of a short cut way that is commonly used for approval of minutes and/or the agenda rather than requiring a motion and second.) Chairman Wormsley: Commissioner Adkins, the first item on the agenda is yours. Commissioner Adkins: Mister Chairman, I would like to make a motion to approve the resolution taking money from the Data Processing Reserve Account in the County Clerk's office and moving it to the equipment line to purchase a laptop computer. Commissioner Carmical: I second the motion. Chairman Wormsley: This resolution has a motion and second. Will the clerk please take the vote. Chairman Wormsley: The resolution passes. We will now take up old business. At our last meeting, Commissioner McKee, your motion to sell property near the airport was deferred to this meeting. You are recognized. Commissioner McKee: I move to withdraw that motion. Chairman Wormsley: Commissioner McKee has moved to withdraw his motion to sell property near the airport. Seeing no objection, this motion is withdrawn. The next item on the agenda is Commissioner Rodgers'. Commissioner Rodgers: I move adopton of the resolution previously provided to each of you to increase the state match local litigation tax in circuit, chancery, and criminal courts to the maximum amounts permissible. This resolution calls for the increases to go to the general fund. Chairman Wormsley: Commissioner Duckett Commissioner Duckett: The sheriff is opposed to this increase. Chairman Wormsley: Commissioner, you are out of order because this motion has not been seconded as needed before the floor is open for discussion or debate. Discussion will begin after we have a second. Is there a second? Commissioner Reinhart: For purposes of discussion, I second the motion. Chairman Wormsley: Commissioner Rodgers is recognized. Commissioner Rodgers: (Speaks about the data on collections, handing out all sorts of numerical figures regarding the litigation tax, and the county's need for additional revenue.) Chairman Wormsley: Commissioner Duckett Commissioner Duckett: I move an amendment to the motion to require 25 percent of the proceeds from the increase in the tax on criminal cases go to fund the sheriff's department. Chairman Wormsley: Commissioner Malone Commissioner Malone: I second the amendment. Chairman Wormsley: A motion has been made and seconded to amend the motion to increase the state match local litigation taxes to the maximum amounts to require 25 percent of the proceeds from the increase in the tax on criminal cases in courts of record going to fund the sheriff's department. Any discussion? Will all those in favor please raise your hand? All those opposed please raise your hand. The amendment carries 17-2. We are now on the motion as amended. Any further discussion? Commissioner Headrick: Does this require a two-thirds vote? Chairman Wormsley: Will the county attorney answer that question? County Attorney Fults: Since these are only courts of record, a majority vote will pass it. The two-thirds requirement is for the general sessions taxes. Chairman Wormsley: Other questions or discussion? Commissioner Adams. Commissioner Adams: Move for a roll call vote. Commissioner Crenshaw: Second Chairman Wormsley: The motion has been made and seconded that the state match local litigation taxes be increased to the maximum amounts allowed by law with 25 percent of the proceeds from the increase in the tax on criminal cases in courts of record going to fund the sheriff's department. Will all those in favor please vote as the clerk calls your name, those in favor vote "aye," those against vote "no." Nine votes for, nine votes against, one not voting. The increase fails. We are now on new business. Commissioner Adkins, the first item on the agenda is yours. Commissioner Adkins: Each of you has previously received a copy of a resolution to increase the wheel tax by $10 to make up the state cut in education funding. I move adoption of this resolution. Chairman Wormsley: Commissioner Thompson Commissioner Thompson: I second. Chairman Wormsley: It has been properly moved and seconded that a resolution increasing the wheel tax by $10 to make up the state cut in education funding be passed. Any discussion? (At this point numerous county commissioners speak for and against increasing the wheel tax and making up the education cuts. This is the first time this resolution is under consideration.) Commissioner Hayes is recognized. Commissioner Hayes: I move previous question. Commisioner Crenshaw: Second. Chairman Wormsley: Previous question has been moved and seconded. As you know, a motion for previous question, if passed by a two-thirds vote, will cut off further debate and require us to vote yes or no on the resolution before us. You should vote for this motion if you wish to cut off further debate of the wheel tax increase at this point. Will all those in favor of previous question please raise your hand? Will all those against please raise your hand? The vote is 17-2. Previous question passes. We are now on the motion to increase the wheel tax by $10 to make up the state cut in education funding. Will all those in favor please raise your hand? Will all those against please raise your hand? The vote is 17-2. This increase passes on first passage. Is there any other new business? Since no member is seeking recognition, are there announcements? Commissioner Hailey. Commissioner Hailey: There will be a meeting of the Budget Committee to look at solid waste funding recommendations on Tuesday, July 16 at noon here in this room. Chairman Wormsley: Any other announcements? The next meeting of this body will be Monday, August 19 at 7 p.m., here in this room. Commissioner Carmical. Commissioner Carmical: There will be a chili supper at County Elementary School on August 16 at 6:30 p.m. Everyone is invited. Chairman Wormsley: Commissioner Austin. Commissioner Austin: Move adjournment. Commissioner Garland: Second. Chairman Wormsley: Without objection, the meeting will stand adjourned. | F31: Action Items with Owners Clerk Correct minutes to include Commissioner McCroskey on the Special Committee on Indigent Care. Record approval of agenda and minutes as amended. Record passage of resolution reallocating funds for laptop purchase. Record withdrawal of airport property sale motion. Record failure of litigation tax increase resolution (tied vote). Record passage of $10 wheel tax increase (first reading). Commissioner Adkins Implement resolution to reallocate Data Processing Reserve funds for laptop purchase. Present resolution to increase wheel tax by $10 (passed on first reading). Commissioner McCroskey Added to Special Committee on Indigent Care. Commissioner McKee Motion to sell airport property withdrawn — no further action required. Commissioner Rodgers Proposed resolution to increase litigation tax (failed after amendment and roll call vote). Commissioner Duckett Amendment requiring 25% of criminal case tax proceeds to fund sheriff’s department (passed, but overall resolution failed). County Attorney Fults Clarified voting requirement: majority vote sufficient for courts of record tax increase. Commissioner Hailey Announced Budget Committee meeting on solid waste funding recommendations: Tuesday, July 16 at noon. Commissioner Carmical Announced chili supper at County Elementary School: August 16 at 6:30 p.m. Chairman Wormsley Scheduled next County Commission meeting: Monday, August 19 at 7 p.m. | G31: Hallucinated-Incorrect
A32: 31 | B32: Summarization | C32: Summarize the following academic abstract in plain language. | D32: Core claim/finding preserved accurately; no overstated or invented conclusions. | E32: Summarize the following academic abstract in plain language.​‌ "Although machine learning has been widely applied to thisprob-lem, three shortcomings prevent its practical application: poorly calibratedprobability scores, SHAP-based explanations whose faithfulness has not beenverified, and models never tested in different regions. SAE-XCrash considers allthree using two public datasets - US-Accidents (7.0 million records, 2016-2023) andUK STATS19 (approximately 1,010,000 records, 2016-2024). Notably, the US-Accidents severity label refers to traffic disruption duration, not injury outcome, andresults should be interpreted accordingly. Previously unknown label-schema drift ledto a revised binary target with Severity 4 as only the positive class; strict temporalsplits are used throughout. FIVE classifiers are compared. Post hoc isotonicCalibration reduces expected calibration. Error by 97.3 per-cent while maintainingnegligible discrimination loss. A four-step SHAP audit confirms that explanationsgenuinely reflect model behavior: deletion-based faithfulness gaps are statisticallysignificant at every feature budget, and insertion gaps are statistically signifi-cant atmore than ten percent of features. Explanation stability holds under conservativenoise levels but degrades at realistic perturbation magnitudes mainly in spatiallysparse geohash cells. In a three-tier cross-dataset transfer experiment - zero-shot,recalibration and full retraining - spatial memorization is the major generalizationbarrier while tem-poral features transfer smoothly between jurisdictions." | F32: This study examined machine learning models for predicting traffic crash severity and addressed three common problems: unreliable probability estimates, unverified explanations of model decisions, and poor performance when applied to data from different regions. Using large accident datasets from the United States and the United Kingdom, the researchers found that calibrating the models greatly improved the accuracy of their risk probabilities without reducing prediction quality. The study also tested whether AI explanations (using SHAP) truly reflected how the models made decisions and found strong evidence that the explanations were generally trustworthy. However, the explanations became less stable when location-related data changed. Finally, when models were applied across countries, the biggest challenge was that they relied too heavily on specific geographic locations, while time-related patterns transferred more successfully between regions. Overall, the research proposes a more reliable and transparent approach for crash-severity prediction and highlights the importance of validating models across different locations. | G32: Correct
A33: 32 | B33: Summarization | C33: Summarize the following financial report excerpt. | D33: Figures cited must match source exactly; no fabricated numbers. | E33: Summarize the following financial report excerpt.​‌ "​‌ Revenue: $192.7 million, up 1% year-over-year, surpassing analyst estimates. Net Income: $37.7 million, more than double the $18.4 million from Q1 2024. Diluted EPS: $0.27, up from $0.13 last year and in line with consensus estimates. Adjusted EBITDA: $56.0 million (29% margin), up from $33.3 million in Q1 2024. Active Clients: 812,000, with Gross Services Volume (GSV) per client rising 3% to $4,912. Free Cash Flow: $30.8 million, up from $12.1 million a year ago Profit Margins: Operating margin rose to 20.1% from 6.8% last year. Guidance: Full-year revenue guidance reaffirmed; adjusted EBITDA guidance raised. " | F33: The company reported a strong quarter, with revenue rising 1% year-over-year to $192.7 million, exceeding analyst expectations. Profitability improved significantly, as net income more than doubled to $37.7 million, diluted EPS increased to $0.27, and adjusted EBITDA grew to $56.0 million, resulting in a 29% margin. Cash generation was also strong, with free cash flow increasing to $30.8 million and operating margin improving from 6.8% to 20.1%. While active clients reached 812,000 and spending per client increased 3%, management reaffirmed full-year revenue guidance and raised its adjusted EBITDA outlook, reflecting confidence in continued earnings growth. | G33: Partially Correct | J33: All figures match source exactly. Downgrade is for the closing line "reflecting confidence in continued earnings growth" — an interpretive/causal claim not stated or implied by the source, which is a bare list of figures with no management commentary. Distinct from other flagged rows (21, 31) where added phrasing was paraphrase of existing source content: this is new synthesized content, not compression.
A34: 33 | B34: Summarization | C34: Summarize the following legal/contract excerpt in plain language. | D34: Key obligations/dates must match source; no invented clauses. | E34: Summarize the following legal/contract excerpt in plain language."LEGAL SERVICES AGREEMENT A. QUESTIONS FOR DISCUSSION 1. How would you translate the following words denoting legal professionals: attorney-at-law, advocate, barrister, and solicitor? In which countries would you most likely hear these expressions? 2. What do you think are the most common provisions contained in a legal services agreement? 3. What obligations are usually imposed on an attorney in a legal services agreement? B. GET THE CONTEXT BEFORE YOU TRANSLATE Attorney's fee, the payment for legal services, can take several forms 1) hourly charge, 2) flat fee for the performance of a particular service (like $250 to write a will), 3) contingent fee (such as one-third of the gross recovery, and nothing if there is no recovery), 4) statutory fees (such as percentages of an estate for representing the estate), 5) court-approved fees (such as in bankruptcy or guardianships), 6) some mixture of hourly and contingent fee or other combination. It is wise (and often mandatory) for the attorney and the client to have a signed contract for any extensive legal work, particularly in contingent fee cases. Most attorneys keep records of time spent on cases to justify fees (and keep track of when actions were taken). A "retainer" is a down payment on fees, often required by the attorney in order to make sure he or she is not left holding the bag for work performed, or at least as a good faith indication that the client is serious and can afford the services. Attorney fee disputes can be decided by arbitration, often operated by the local bar association. Attorney's fees are not awarded to the winning party in a lawsuit except where there is a provision in a contract for the fees or there is a statute which provides for an award of fees in the particular type of case." | F34: This excerpt explains how legal service fees work and what is typically included in agreements between attorneys and clients. Lawyers may charge by the hour, a fixed fee, a percentage of money recovered in a case (contingency fee), or other court- or law-based fee arrangements. For significant legal work, attorneys and clients usually sign a contract, and clients may be asked to pay a retainer (an upfront payment) before work begins. Attorneys often keep detailed time records to support their fees, and disputes over fees can sometimes be resolved through arbitration. In most lawsuits, the winning party does not automatically receive reimbursement for attorney fees unless a contract or specific law allows it. | G34: Correct
A35: 34 | B35: Summarization | C35: Summarize the following product review in one sentence. | D35: Sentiment and key point must match source; no invented pros/cons. | E35: Summarize the following product review in one sentence.​‌ "​‌ Product Review Sample Structure 1. General Information Product Name: UltraClean Cordless Vacuum X100 Manufacturer: Apex Home Appliances Reviewer: Jane Doe Date of Testing: August 20, 2026 2. Product Description Overview: A lightweight, bagless cordless stick vacuum designed for hard floors and low-pile carpets. Key Features: 45-minute runtime, LED headlight, HEPA filtration system, and 3 power modes. 3. Evaluation Criteria & Testing Performance: Strong suction on hard wood; struggles slightly with deep-set pet hair on thick carpets unless using max mode. Design & Weight: Weighs only 5.2 lbs; very easy to maneuver overhead and under furniture. Battery Life: Lasts about 42 minutes on standard mode, but drops to 12 minutes on turbo boost. 4. Pros and Cons Pros: Lightweight and ergonomic design. Easy-to-empty dust bin. Quiet operation compared to older models. Cons: Short battery life on turbo mode. Small dust capacity requires frequent emptying. "​‌ | F35: The UltraClean Cordless Vacuum X100 is a lightweight and easy-to-maneuver cordless vacuum that delivers strong cleaning performance on hard floors and useful features such as HEPA filtration and multiple power modes, though its battery life drops significantly on turbo mode and its small dust bin requires frequent emptying. | G35: Correct
A36: 35 | B36: Summarization | C36: Summarize the following how-to guide into 5 steps. | D36: Steps must match source order and content; no invented or reordered steps. | E36: Summarize the following how-to guide into 5 steps.​‌ "​‌ Structure of a How-To Guide PDF A good how-to guide has clear sections to help the reader learn a task. Title: Tells what the guide teaches. Introduction: Explains why the skill or task matters. Requirements: Lists tools or items needed before you start. Steps: Breaks the work into numbered actions. Troubleshooting: Gives fixes for common mistakes. " | F36: Add a clear title that states what task or skill the guide teaches. Write an introduction explaining why the task is useful or important. List the requirements by identifying the tools, materials, or resources needed. Provide numbered instructions that break the task into simple, sequential steps. Include troubleshooting tips to help users solve common problems or mistakes. | G36: Correct
A37: 36 | B37: Summarization | C37: Summarize the following press release, identifying the main announcement. | D37: Correct main announcement; no fabricated details. | E37: Summarize the following press release, identifying the main announcement.​‌ "Sample press releases This page provides sample press releases and public statements for different radiological emergencies. Holding statement Press release for a radiological emergency involving RDD or for a transport emergency Press release for a lost or stolen source Press release for the discovery of a dangerous source in a public place (e.g. customs or post office) Note that these examples must be reviewed carefully and revised to conform with a specific emergency situation. The content of a press release should be approved by the incident commander." | F37: Summary: The main announcement is the availability of sample press releases and public statements for various radiological emergency scenarios, including transport incidents, lost or stolen radioactive sources, and the discovery of dangerous sources in public places. The document provides templates to support emergency communications but emphasizes that each example must be adapted to the specific situation and approved by the incident commander before release. | G37: Correct
A38: 37 | B38: Summarization | C38: Summarize the following forum thread, identifying the consensus view. | D38: Correct majority view as reflected in source; no invented consensus. | E38: Summarize the following forum thread, identifying the consensus view.​‌ "Problems and Purpose Like consensus conferences, consensus forums are a popular method of deliberative democracy when complex, broad policy issues require a workable if not peaceable agreement among disparate groups. Where the two differ is in the number of active participants in the plenary session. While consensus conferences call together a limited number of people (10-15) to formulate questions to a panel of experts and so come to a decision, consensus forums often involve 80-130 individuals who work in small groups to develop points of consensus (NCDD 2008). The forum format is more amenable to situations in which the policy issue is sufficiently broad to demand a range of suggested approaches rather than one plan of attack (Aspiri 2010). For example, consensus conferences tend to be used in the area science and technology to determine which kinds of advancements should or should not be pursued. Consensus forums are often deployed in broader policy areas such as sustainability and the environment where a number of different approaches may be taken to effect the same result. Deliberative democracy scholar and practitioner Janette Hartz-Karp defines consensus as "accepting differences and working together on common ground and/or agreeing on a process to make decisions (rather than mediation, conflict resolution, or Alternative Dispute Resolution)" (Hartz-Karp 2004). " | F38: Summary The passage explains the purpose and structure of consensus forums, a form of deliberative democracy used to address complex public policy issues. Unlike consensus conferences, which involve a small group of participants working toward a specific decision, consensus forums typically involve 80 to 130 participants who work in smaller groups to develop areas of agreement. They are especially useful for broad issues, such as sustainability and environmental policy, where multiple solutions may be appropriate rather than a single course of action. Consensus View The consensus view presented is that consensus forums are an effective way to bring diverse stakeholders together to identify common ground on complex policy issues. Rather than eliminating differences or forcing complete agreement, participants seek to accept differing perspectives, collaborate on shared goals, and agree on decision-making processes, enabling constructive progress on broad public policy challenges. | G38: Hallucinated-Incorrect | J38: Confirmed: "effective way to bring diverse stakeholders together" is unsupported evaluative language, not in source. Larger issue: source is an academic/definitional passage about consensus forums as a method (no actual forum debate or participants), not a real forum thread — same source/prompt mismatch as row 30. The entire "Consensus View" section synthesizes a consensus that was never reported, rather than flagging that the source contains no actual forum discussion to summarize.
A39: 38 | B39: Summarization | C39: Summarize the following policy document excerpt. | D39: Correct scope/effective date if stated; no fabricated dates. | E39: Summarize the following policy document excerpt.​‌ "A short-form policy document excerpt typically contains a metadata header, a concise policy statement, and basic implementation rules. Short-Form Policy Sample Excerpt Document ID: POL-REM-001 Effective Date: September 1, 2026 Subject: Remote Work Core Hours & Availability 1. Purpose This policy defines minimum communication and availability expectations for all full-time remote staff. 2. Scope Applies to all employees working outside a designated corporate office location more than two days per week. 3. Policy Statement All remote employees must remain accessible via corporate messaging platforms and email during core operational hours (10:00 AM – 3:00 PM local time). Unplanned absences or offline periods exceeding 60 minutes during core hours must be communicated immediately to the direct supervisor. Failure to maintain availability without prior notice may result in a formal review of remote work privileges. 4. Responsibilities Employee: Ensure reliable internet connection and active status during core windows. Manager: Monitor team communication and approve schedule exceptions." | F39: Summary: Policy POL-REM-001, effective September 1, 2026, establishes communication and availability requirements for full-time remote employees working outside a corporate office more than two days per week. Employees must be reachable via company messaging platforms and email during core hours (10:00 AM to 3:00 PM local time) and must promptly notify their supervisor of absences exceeding 60 minutes. Employees are responsible for maintaining reliable connectivity and active status, while managers oversee communication and approve scheduling exceptions; failure to meet availability requirements may lead to a review of remote work privileges. | G39: Correct
A40: 39 | B40: Summarization | C40: Summarize the following research paper's methodology section. | D40: Method steps must match source; no invented methodology. | E40: Summarize the following research paper's methodology section.​‌ "Methodology On the research methodology parameter, as shown in Table (2), 18 (40%) agreed on knowing to make a good research methodology. This finding reflects the confusion and misconception as on the level of attitude previously, most of the students disagreed with knowing how to write a research paper. The general information they get from the supervisors does not start writing the papers. Linking to this challenge, 24 (53.3%) of the total 45 students believed they lack having an obvious idea of how to collect data for their research, and this led to another hurdle in shaping the correct research methodology. On the other hand, 24 (53.4%) know how to write both the introduction and conclusion of the research paper since they have taken essay courses in their academic years. 26 (57.8%) students agreed they understand how to organize ideas. Another important finding is that 27(60%) of the students face difficulty in paraphrasing the selected information from resources. Most students misunderstand the difference between paraphrasing and summarizing. Sometimes students face difficulties in finding the right word and sentence structure that fits the selected resource information without changing the original content. In other words, students need to understand how to paraphrase or they would fall under the trap of Plagiarism (Yulia, 2012)" | F40: Methodology Summary The methodology section reports survey results from 45 students regarding their research-methodology skills and challenges. The findings show that only 40% of students believed they knew how to develop a sound research methodology, indicating uncertainty about the research-writing process. More than half (53.3%) reported lacking a clear understanding of how to collect research data, which hindered their ability to design an appropriate methodology. Despite these challenges, 53.4% of students felt capable of writing research-paper introductions and conclusions, and 57.8% said they could organize ideas effectively. However, 60% reported difficulties with paraphrasing information from sources, often confusing paraphrasing with summarizing and struggling to rephrase content without altering its meaning. The study highlights weaknesses in research-methodology knowledge, data-collection skills, and paraphrasing, while noting stronger abilities in basic academic writing and organization. | G40: Correct
A41: 40 | B41: Summarization | C41: Summarize the following long email chain into a single-paragraph status update. | D41: Correct current status as of the last message; no invented status. | E41: Summarize the following long email chain into a single-paragraph status update.​‌ " Email 1: Initial Request From: Sarah Jenkins s.jenkins@clientcorp.com To: Alex Rivera a.rivera@creativeagency.com Date: October 12, 2026, 9:15 AM Subject: Q4 Website Redesign - Timeline Check Hi Alex, I hope you are having a good week. Our team met this morning to review the current assets for the Q4 website redesign. We noticed a few delays on our end regarding the final brand guidelines sign-off. Do you think this will push our scheduled launch date of November 15? Let me know your thoughts when you have a moment. Best, Sarah Email 2: First Reply From: Alex Rivera a.rivera@creativeagency.com To: Sarah Jenkins s.jenkins@clientcorp.com Cc: Mark Chen m.chen@creativeagency.com Date: October 12, 2026, 11:40 AM Subject: Re: Q4 Website Redesign - Timeline Check Hi Sarah, Thanks for reaching out. I have copied Mark, our lead developer, on this thread. A delay with the brand guidelines sign-off will impact our development phase. If we do not receive the final assets by this Friday, we will likely need to push the launch by about two weeks to late November. Let's hold a quick 15-minute call tomorrow to look at the schedule and see what we can adjust. Does 10:00 AM work for you? Regards, Alex Email 3: Latest Reply (Closing the loop) From: Sarah Jenkins s.jenkins@clientcorp.com To: Alex Rivera a.rivera@creativeagency.com, Mark Chen m.chen@creativeagency.com Date: October 12, 2026, 1:05 PM Subject: Re: Q4 Website Redesign - Timeline Check Hi Alex and Mark, 10:00 AM tomorrow works great for me. I will send over a calendar invite shortly. We are pushing hard to get the brand guidelines approved internally before then, so maybe we can lock down a revised timeline during the call. Look forward to speaking then. Best, Sarah​‌ " | F41: The Q4 website redesign remains at risk due to delays in the client’s internal approval of final brand guidelines. The agency indicated that if the final assets are not received by Friday, the planned November 15 launch will likely be postponed by approximately two weeks to late November. To address the issue, both teams have scheduled a 10:00 AM meeting the following day to review the project schedule and finalize a revised timeline if necessary. The client is actively working to secure approval before the meeting in hopes of minimizing any impact on the launch date. | G41: Correct
A42: 41 | B42: Code Generation | C42: Write a Python function that returns the factorial of a non-negative integer n. | D42: Correct recursive or iterative implementation; handles n=0 returning 1. | F42: Here's a simple Python function that returns the factorial of a non-negative integer n: def factorial(n): if n < 0: raise ValueError("n must be a non-negative integer") result = 1 for i in range(2, n + 1): result *= i return result Example Usage print(factorial(0)) # 1 print(factorial(5)) # 120 print(factorial(7)) # 5040 The factorial of n is defined as: 0! = 1 n! = n × (n−1) × (n−2) × ... × 1 for n > 0 | G42: Correct
A43: 42 | B43: Code Generation | C43: Write a Python function to check if a string is a palindrome. | D43: Correctly handles case and returns boolean; no off-by-one errors. | F43: The image contains the text: "Write a Python function to check if a string is a palindrome." Here's a simple Python function: def is_palindrome(s): return s == s[::-1] Example usage: print(is_palindrome("radar")) # True print(is_palindrome("hello")) # False A palindrome is a string that reads the same forward and backward, such as "radar", "madam", or "level". | G43: Partially Correct | J43: Ground truth requires case-insensitive handling; function does raw s == s[::-1] with no normalization. Fails on mixed-case input, e.g. is_palindrome("Racecar") returns False. Bug not visible in the response's own examples (both lowercase). Otherwise correct logic.
A44: 43 | B44: Code Generation | C44: Write a SQL query to select all rows from table 'employees' where salary > 50000. | D44: Valid SQL syntax; correct WHERE clause; no invented columns/tables. | F44: SELECT * FROM employees WHERE salary > 50000; This query selects all columns (*) from the employees table and returns only the rows where the salary value is greater than 50,000. | G44: Correct
